<?xml version="0.0" ?>
<robot name="urdf_robot">
  <link name="world"/>
  <link name="link0_x">
		<inertial>
			<origin rpy="0.00000 -0.00000 0.00000" xyz="0.00000 0.00000 0.00000"/>
			<mass value="0.00000"/>
			<inertia ixx="0.00000" ixy="0" ixz="0" iyy="0.00000" iyz="0" izz="0.00000"/>
		</inertial>
	</link>
	<joint name="joint0" type="prismatic">
    <parent link="world"/>
    <child link="link0_x"/>
    <origin rpy="0 0 0" xyz="0 0 0"/>
    <axis xyz="1 0 0"/>
    <dynamics damping="1.0" friction="1.0"/>
    <limit lower="-1000" upper="1000" />
  </joint>
  
	<link name="link0_y">
		<inertial>
			<origin rpy="0.00000 -0.00000 0.00000" xyz="0.00000 0.00000 0.00000"/>
			<mass value="0.00000"/>
			<inertia ixx="0.00000" ixy="0" ixz="0" iyy="0.00000" iyz="0" izz="0.00000"/>
		</inertial>
	</link>
	<joint name="joint1" type="prismatic">
    <parent link="link0_x"/>
    <child link="link0_y"/>
    <origin rpy="0 0 0" xyz="0 0 0"/>
    <axis xyz="0 1 0"/>
    <dynamics damping="1.0" friction="1.0"/>
    <limit lower="-1000" upper="1000" />
  </joint>
	<link name="link0_z">
		<inertial>
			<origin rpy="0.00000 -0.00000 0.00000" xyz="0.00000 0.00000 0.00000"/>
			<mass value="0.00000"/>
			<inertia ixx="0.00000" ixy="0" ixz="0" iyy="0.00000" iyz="0" izz="0.00000"/>
		</inertial>
	</link>
	<joint name="joint2" type="prismatic">
    <parent link="link0_y"/>
    <child link="link0_z"/>
    <origin rpy="0 0 0" xyz="0 0 0"/>
    <axis xyz="0 0 1"/>
    <dynamics damping="1.0" friction="1.0"/>
    <limit lower="-1000" upper="1000" />
  </joint>
  
  <link name="link0_rotx">
		<inertial>
			<origin rpy="0.00000 -0.00000 0.00000" xyz="0.00000 0.00000 0.00000"/>
			<mass value="0.00000"/>
			<inertia ixx="0.00000" ixy="0" ixz="0" iyy="0.00000" iyz="0" izz="0.00000"/>
		</inertial>
	</link>
	<joint name="joint_rotx" type="continuous">
    <parent link="link0_z"/>
    <child link="link0_rotx"/>
    <origin rpy="0 0 0" xyz="0 0 0"/>
    <axis xyz="1 0 0"/>
    <dynamics damping="1.0" friction="1.0"/>
    <limit lower="-1000" upper="1000" />
  </joint>
  
    <link name="link0_roty">
		<inertial>
			<origin rpy="0.00000 -0.00000 0.00000" xyz="0.00000 0.00000 0.00000"/>
			<mass value="0.00000"/>
			<inertia ixx="0.00000" ixy="0" ixz="0" iyy="0.00000" iyz="0" izz="0.00000"/>
		</inertial>
	</link>
	<joint name="joint_roty" type="continuous">
    <parent link="link0_rotx"/>
    <child link="link0_roty"/>
    <origin rpy="0 0 0" xyz="0 0 0"/>
    <axis xyz="0 1 0"/>
    <dynamics damping="1.0" friction="1.0"/>
    <limit lower="-1000" upper="1000" />
  </joint>
  
	<joint name="joint_rotz" type="continuous">
    <parent link="link0_roty"/>
    <child link="baseLink2"/>
    <origin rpy="0 0 0" xyz="0 0 0"/>
    <axis xyz="0 0 1"/>
    <dynamics damping="1.0" friction="1.0"/>
  </joint>
  <link name="baseLink2">
    <inertial>
      <origin rpy="0 0 0" xyz="0 1 0"/>
       <mass value="10.0"/>
       <inertia ixx="1.67334" ixy="0" ixz="0" iyy="1.67334" iyz="0" izz="1.67334"/>
    </inertial>
    <visual>
      <origin rpy="0 0 0" xyz="0 0 0"/>
      <geometry>
<mesh filename="cube.obj" scale="1 1 1"/>      
      </geometry>
      <material name="white">
        <color rgba="1 1 1 1"/>
        <specular rgb="11 1 1"/>
      </material>
    </visual>
    <collision>
      <origin rpy="0 0 0" xyz="0.4 0.4 0.4"/>
      <geometry>
	 		<sphere radius="0.1"/>
      </geometry>
    </collision>
    <collision>
      <origin rpy="0 0 0" xyz="-0.4 0.4 0.4"/>
      <geometry>
	 		<sphere radius="0.1"/>
      </geometry>
    </collision><collision>
      <origin rpy="0 0 0" xyz="0.4 -0.4 0.4"/>
      <geometry>
	 		<sphere radius="0.1"/>
      </geometry>
    </collision><collision>
      <origin rpy="0 0 0" xyz="-0.4 -0.4 0.4"/>
      <geometry>
	 		<sphere radius="0.1"/>
      </geometry>
    </collision><collision>
      <origin rpy="0 0 0" xyz="0.4 0.4 -0.4"/>
      <geometry>
	 		<sphere radius="0.1"/>
      </geometry>
    </collision><collision>
      <origin rpy="0 0 0" xyz="-0.4 0.4 -0.4"/>
      <geometry>
	 		<sphere radius="0.1"/>
      </geometry>
    </collision><collision>
      <origin rpy="0 0 0" xyz="0.4 -0.4 -0.4"/>
      <geometry>
	 		<sphere radius="0.1"/>
      </geometry>
    </collision><collision>
      <origin rpy="0 0 0" xyz="-0.4 -0.4 -0.4"/>
      <geometry>
	 		<sphere radius="0.1"/>
      </geometry>
    </collision>
  </link>
</robot>

