<?xml version="1.0" ?>
<robot name="panda" xmlns:xacro="http://www.ros.org/wiki/xacro">
  <link name="panda_link0">
  	<inertial>
      <origin rpy="0 0 0" xyz="0 0 0.05"/>
       <mass value="2.9"/>
       <inertia ixx="0.1" ixy="0" ixz="0" iyy="0.1" iyz="0" izz="0.1"/>
    </inertial>
    <visual>
      <geometry>
        <mesh filename="meshes/collision/link0.obj"/>
      </geometry>
      <material name="panda_white">
    		<color rgba="1. 1. 1. 1."/>
  		</material>
    </visual>
    <collision>
      <geometry>
        <mesh filename="meshes/collision/link0.obj"/>
      </geometry>
      <material name="panda_white"/>
    </collision>
  </link>
  <link name="panda_link1">
  	<inertial>
      <origin rpy="0 0 0" xyz="0 -0.04 -0.05"/>
       <mass value="2.7"/>
       <inertia ixx="0.1" ixy="0" ixz="0" iyy="0.1" iyz="0" izz="0.1"/>
    </inertial>
    <visual>
      <geometry>
        <mesh filename="meshes/visual/link1.obj"/>
      </geometry>
      <material name="panda_white"/>
    </visual>
    <collision>
      <geometry>
        <mesh filename="meshes/collision/link1.obj"/>
      </geometry>
      <material name="panda_white"/>
    </collision>
  </link>
  <joint name="panda_joint1" type="fixed">
    <safety_controller k_position="100.0" k_velocity="40.0" soft_lower_limit="-2.8973" soft_upper_limit="2.8973"/>
    <origin rpy="0 0 0" xyz="0 0 0.333"/>
    <parent link="panda_link0"/>
    <child link="panda_link1"/>
    <axis xyz="0 0 1"/>
    <limit effort="87" lower="-2.9671" upper="2.9671" velocity="2.1750"/>
  </joint>
  <link name="panda_link2">
  	<inertial>
      <origin rpy="0 0 0" xyz="0 -0.04 0.06"/>
       <mass value="2.73"/>
       <inertia ixx="0.1" ixy="0" ixz="0" iyy="0.1" iyz="0" izz="0.1"/>
    </inertial>
    <visual>
      <geometry>
        <mesh filename="meshes/visual/link2.obj"/>
      </geometry>
      <material name="panda_white"/>
    </visual>
    <collision>
      <geometry>
        <mesh filename="meshes/collision/link2.obj"/>
      </geometry>
      <material name="panda_white"/>
    </collision>
  </link>
  <joint name="panda_joint2" type="fixed">
    <safety_controller k_position="100.0" k_velocity="40.0" soft_lower_limit="-1.7628" soft_upper_limit="1.7628"/>
    <origin rpy="-1.57079632679 0 0" xyz="0 0 0"/>
    <parent link="panda_link1"/>
    <child link="panda_link2"/>
    <axis xyz="0 0 1"/>
    <limit effort="87" lower="-1.8326" upper="1.8326" velocity="2.1750"/>
  </joint>
  <link name="panda_link3">
	  <inertial>
      <origin rpy="0 0 0" xyz="0.01 0.01 -0.05"/>
       <mass value="2.04"/>
       <inertia ixx="0.1" ixy="0" ixz="0" iyy="0.1" iyz="0" izz="0.1"/>
    </inertial>
    <visual>
      <geometry>
        <mesh filename="meshes/visual/link3.obj"/>
      </geometry>
      <material name="panda_red">
    		<color rgba="1. 1. 1. 1."/>
  		</material>
    </visual>
    <collision>
      <geometry>
        <mesh filename="meshes/collision/link3.obj"/>
      </geometry>
    </collision>
  </link>
  <joint name="panda_joint3" type="fixed">
    <safety_controller k_position="100.0" k_velocity="40.0" soft_lower_limit="-2.8973" soft_upper_limit="2.8973"/>
    <origin rpy="1.57079632679 0 0" xyz="0 -0.316 0"/>
    <parent link="panda_link2"/>
    <child link="panda_link3"/>
    <axis xyz="0 0 1"/>
    <limit effort="87" lower="-2.9671" upper="2.9671" velocity="2.1750"/>
  </joint>
  <link name="panda_link4">
  	<inertial>
      <origin rpy="0 0 0" xyz="-0.03 0.03 0.02"/>
       <mass value="2.08"/>
       <inertia ixx="0.1" ixy="0" ixz="0" iyy="0.1" iyz="0" izz="0.1"/>
    </inertial>
    <visual>
      <geometry>
        <mesh filename="meshes/visual/link4.obj"/>
      </geometry>
      <material name="panda_white"/>
    </visual>
    <collision>
      <geometry>
        <mesh filename="meshes/collision/link4.obj"/>
      </geometry>
      <material name="panda_white"/>
    </collision>
  </link>
  <joint name="panda_joint4" type="fixed">
    <safety_controller k_position="100.0" k_velocity="40.0" soft_lower_limit="-3.0718" soft_upper_limit="-0.0698"/>
    <origin rpy="1.57079632679 0 0" xyz="0.0825 0 0"/>
    <parent link="panda_link3"/>
    <child link="panda_link4"/>
    <axis xyz="0 0 1"/>
    <limit effort="87" lower="-3.1416" upper="0.0" velocity="2.1750"/>
  </joint>
  <link name="panda_link5">
  	<inertial>
      <origin rpy="0 0 0" xyz="0 0.04 -0.12"/>
       <mass value="3"/>
       <inertia ixx="0.1" ixy="0" ixz="0" iyy="0.1" iyz="0" izz="0.1"/>
    </inertial>
    <visual>
      <geometry>
        <mesh filename="meshes/visual/link5.obj"/>
      </geometry>
      <material name="panda_white"/>
    </visual>
    <collision>
      <geometry>
        <mesh filename="meshes/collision/link5.obj"/>
      </geometry>
      <material name="panda_white"/>
    </collision>
  </link>
  <joint name="panda_joint5" type="fixed">
    <safety_controller k_position="100.0" k_velocity="40.0" soft_lower_limit="-2.8973" soft_upper_limit="2.8973"/>
    <origin rpy="-1.57079632679 0 0" xyz="-0.0825 0.384 0"/>
    <parent link="panda_link4"/>
    <child link="panda_link5"/>
    <axis xyz="0 0 1"/>
    <limit effort="12" lower="-2.9671" upper="2.9671" velocity="2.6100"/>
  </joint>
  <link name="panda_link6">
  	<inertial>
      <origin rpy="0 0 0" xyz="0.04 0 0"/>
       <mass value="1.3"/>
       <inertia ixx="0.1" ixy="0" ixz="0" iyy="0.1" iyz="0" izz="0.1"/>
    </inertial>
    <visual>
      <geometry>
        <mesh filename="meshes/visual/link6.obj"/>
      </geometry>
      <material name="panda_white"/>
    </visual>
    <collision>
      <geometry>
        <mesh filename="meshes/collision/link6.obj"/>
      </geometry>
      <material name="panda_white"/>
    </collision>
  </link>
  <joint name="panda_joint6" type="fixed">
    <safety_controller k_position="100.0" k_velocity="40.0" soft_lower_limit="-0.0175" soft_upper_limit="3.7525"/>
    <origin rpy="1.57079632679 0 0" xyz="0 0 0"/>
    <parent link="panda_link5"/>
    <child link="panda_link6"/>
    <axis xyz="0 0 1"/>
    <limit effort="12" lower="-0.0873" upper="3.8223" velocity="2.6100"/>
  </joint>
  <link name="panda_link7">
  	<inertial>
      <origin rpy="0 0 0" xyz="0 0 0.08"/>
       <mass value=".2"/>
       <inertia ixx="0.1" ixy="0" ixz="0" iyy="0.1" iyz="0" izz="0.1"/>
    </inertial>
    <visual>
      <geometry>
        <mesh filename="meshes/collision/link7.obj"/>
      </geometry>
      <material name="panda_white"/>
    </visual>
    <collision>
      <geometry>
        <mesh filename="meshes/collision/link7.obj"/>
      </geometry>
      <material name="panda_white"/>
    </collision>
  </link>
  <joint name="panda_joint7" type="fixed">
    <safety_controller k_position="100.0" k_velocity="40.0" soft_lower_limit="-2.8973" soft_upper_limit="2.8973"/>
    <origin rpy="1.57079632679 0 0" xyz="0.088 0 0"/>
    <parent link="panda_link6"/>
    <child link="panda_link7"/>
    <axis xyz="0 0 1"/>
    <limit effort="12" lower="-2.9671" upper="2.9671" velocity="2.6100"/>
  </joint>
  <!-- <link name="panda_link8">
  	 <inertial>
      <origin rpy="0 0 0" xyz="0 0 0"/>
       <mass value="0.0"/>
       <inertia ixx="0.1" ixy="0" ixz="0" iyy="0.1" iyz="0" izz="0.1"/>
    </inertial>
  </link> -->
  <!-- <joint name="panda_joint8" type="fixed">
    <origin rpy="0 0 0" xyz="0 0 0.107"/>
    <parent link="panda_link7"/>
    <child link="panda_link8"/>
    <axis xyz="0 0 0"/>
  </joint>
  <joint name="panda_universal_joint_top_joint" type="fixed">
    <parent link="panda_link8"/>
    <child link="universal_joint_top"/>
    <origin rpy="1.5707 0 0.785398163397" xyz="0 0 0.0"/>
  </joint> -->
  
  <!-- <joint name="panda_universal_joint_top_joint" type="continuous">
    <parent link="panda_link7"/>
    <child link="universal_joint_top"/>
    <origin rpy="1.5707 0 1.5707" xyz="0.0 0.04 0.0"/>
  </joint>
  <link name="universal_joint_top">
    <inertial>
      <origin rpy="1.5707 0 0.785398163397" xyz="0 0 0.0"/>
      <mass value=".1"/>
      <inertia ixx="0.05" ixy="0" ixz="0" iyy="0.05" iyz="0" izz="0.05"/>
    </inertial>
    <visual>
      <origin rpy="0 0 0" xyz="0 0 0"/>
      <geometry>
        <mesh filename="meshes/visual/universal_joint.obj" />
      </geometry>
      <material name="white">
        <color rgba="1 1 1 1"/>
      </material>
    </visual>
  </link>
  <joint name="universal_joint_top_universal_joint_cross_joint" type="continuous">
    <parent link="universal_joint_top"/>
    <child link="universal_joint_cross"/>
    <origin rpy="1.5707 0 1.5707" xyz="0.0 0.04 0.0"/>
  </joint>
  <link name="universal_joint_cross">
    <inertial>
      <origin rpy="0 0 0" xyz="0 0 0"/>
      <mass value=".1"/>
      <inertia ixx="0.05" ixy="0" ixz="0" iyy="0.05" iyz="0" izz="0.05"/>
    </inertial>
    <visual>
      <origin rpy="0 0 0" xyz="0 0 0"/>
      <geometry>
        <mesh filename="meshes/visual/universal_joint_cross.obj" />
      </geometry>
      <material name="white">
        <color rgba="1 1 1 1"/>
      </material>
    </visual>
  </link>
  <joint name="universal_joint_cross_universal_joint_bottom_joint" type="continuous">
    <parent link="universal_joint_cross"/>
    <child link="universal_joint_bottom"/>
    <origin rpy="1.5707 0 0" xyz="0.0 0.0 0.0"/>
  </joint>
  <link name="universal_joint_bottom">
    <inertial>
      <origin rpy="0 1.5707 1.5707" xyz="0.04 0 0"/>
      <mass value=".1"/>
      <inertia ixx="0.05" ixy="0" ixz="0" iyy="0.05" iyz="0" izz="0.05"/>
    </inertial>
    <visual>
      <origin rpy="0 1.5707 1.5707" xyz="0.04 0 0"/>
      <geometry>
        <mesh filename="meshes/visual/universal_joint.obj" />
      </geometry>
      <material name="white">
        <color rgba="1 1 1 1"/>
      </material>
    </visual>
  </link> -->
  
  <!-- Pendulum -->
  <material name="Blue">
    <color rgba="0.28 0.52 0.92 1.0"/>
  </material>
  <link name="link0">
    <visual>
      <geometry>
        <mesh filename="meshes/visual/sphere_smooth.obj" scale="0.03 0.03 0.03" />
      </geometry>
      <origin rpy="0 0 0" xyz="0 0.3 0"/>
      <material name="Blue"/>
    </visual>
    <collision>
      <geometry>
        <mesh filename="meshes/visual/sphere_smooth.obj" scale="0.03 0.03 0.03" />
      </geometry>
      <origin rpy="0 0 0" xyz="0 0.3 0"/>
    </collision>
    <inertial>
      <origin rpy="0 0 0" xyz="0.0 0.3 0.0"/>
      <mass value="1."/>
      <inertia ixx="0.00494875" ixy="0" ixz="0" iyy="0.00494174" iyz="0" izz="0.002219"/>
    </inertial>
  </link>
  <joint name="joint0" type="continuous">
    <parent link="panda_link7"/>
    <child link="link0"/>
    <origin rpy="0 0 0" xyz="0 0 0"/>
    <axis xyz="1 0 0"/>
    <dynamics damping="1.0" friction="1.0"/>
  </joint>
  <!-- <joint name="joint0" type="continuous">
    <parent link="universal_joint_bottom"/>
    <child link="link0"/>
    <origin rpy="0 0 0" xyz="0 0 0"/>
    <axis xyz="1 0 0"/>
    <dynamics damping="1.0" friction="1.0"/>
  </joint> -->
  <link name="link1">
    <visual>
      <geometry>
        <mesh filename="meshes/visual/sphere_smooth.obj" scale="0.03 0.03 0.03" />
      </geometry>
      <origin rpy="0 0 0" xyz="0 0.3 0"/>
      <material name="Red"/>
    </visual>
    <collision>
      <geometry>
        <mesh filename="meshes/visual/sphere_smooth.obj" scale="0.03 0.03 0.03" />
      </geometry>
      <origin rpy="0 0 0" xyz="0 0.3 0"/>
    </collision>
    <inertial>
      <origin rpy="0 0 0" xyz="0 0.3 0"/>
      <mass value="2.16"/>
      <inertia ixx="0.00539427" ixy="0" ixz="0" iyy="0.0048979" iyz="0" izz="0.00311573"/>
    </inertial>
  </link>
  <joint name="joint1" type="continuous">
    <parent link="link0"/>
    <child link="link1"/>
    <origin rpy="0 0 0" xyz="0 0.3 0"/>
    <axis xyz="1 0 0"/>
    <dynamics damping="1.0" friction="1.0"/>
  </joint>
 <!--<link name="link2">
    <visual>
      <geometry>
        <mesh filename="meshes/visual/sphere_smooth.obj" scale="0.03 0.03 0.03" />
      </geometry>
      <origin rpy="0 0 0" xyz="0 0.3 0"/>
      <material name="Red"/>
    </visual>
    <collision>
      <geometry>
        <mesh filename="meshes/visual/sphere_smooth.obj" scale="0.03 0.03 0.03" />
      </geometry>
      <origin rpy="0 0 0" xyz="0 0.3 0"/>
    </collision>
    <inertial>
      <origin rpy="0 0 0" xyz="0 0.3 0"/>
      <mass value="2.16"/>
      <inertia ixx="0.00539427" ixy="0" ixz="0" iyy="0.0048979" iyz="0" izz="0.00311573"/>
    </inertial>
  </link>
  <joint name="joint2" type="continuous">
    <parent link="link1"/>
    <child link="link2"/>
    <origin rpy="0 0 0" xyz="0 0.3 0"/>
    <axis xyz="1 0 0"/>
    <dynamics damping="1.0" friction="1.0"/>
  </joint> -->
  <!-- <link name="link3">
    <visual>
      <geometry>
        <mesh filename="meshes/visual/sphere_smooth.obj" scale="0.03 0.03 0.03" />
      </geometry>
      <origin rpy="0 0 0" xyz="0 0.3 0"/>
      <material name="Red"/>
    </visual>
    <collision>
      <geometry>
        <mesh filename="meshes/visual/sphere_smooth.obj" scale="0.03 0.03 0.03" />
      </geometry>
      <origin rpy="0 0 0" xyz="0 0.3 0"/>
    </collision>
    <inertial>
      <origin rpy="0 0 0" xyz="0 0.3 0"/>
      <mass value="2.16"/>
      <inertia ixx="0.00539427" ixy="0" ixz="0" iyy="0.0048979" iyz="0" izz="0.00311573"/>
    </inertial>
  </link>
  <joint name="joint3" type="continuous">
    <parent link="link2"/>
    <child link="link3"/>
    <origin rpy="0 0 0" xyz="0 0.3 0"/>
    <axis xyz="1 0 0"/>
    <dynamics damping="1.0" friction="1.0"/>
  </joint>
   <link name="link4">
    <visual>
      <geometry>
        <mesh filename="meshes/visual/sphere_smooth.obj" scale="0.03 0.03 0.03" />
      </geometry>
      <origin rpy="0 0 0" xyz="0 0.3 0"/>
      <material name="Red"/>
    </visual>
    <collision>
      <geometry>
        <mesh filename="meshes/visual/sphere_smooth.obj" scale="0.03 0.03 0.03" />
      </geometry>
      <origin rpy="0 0 0" xyz="0 0.3 0"/>
    </collision>
    <inertial>
      <origin rpy="0 0 0" xyz="0 0.3 0"/>
      <mass value="2.16"/>
      <inertia ixx="0.00539427" ixy="0" ixz="0" iyy="0.0048979" iyz="0" izz="0.00311573"/>
    </inertial>
  </link>
  <joint name="joint4" type="continuous">
    <parent link="link3"/>
    <child link="link4"/>
    <origin rpy="0 0 0" xyz="0 0.3 0"/>
    <axis xyz="1 0 0"/>
    <dynamics damping="1.0" friction="1.0"/>
  </joint> -->
</robot>