<?xml version="1.0" ?>
<robot name="urdf_door">
  
  
  <link name="world"/>
   <link name="link0_x">
		<inertial>
			<origin rpy="0.00000 -0.00000 0.00000" xyz="0.00000 0.00000 0.00000"/>
			<mass value="0.00000"/>
			<inertia ixx="0.00000" ixy="0" ixz="0" iyy="0.00000" iyz="0" izz="0.00000"/>
		</inertial>
	</link>
	<joint name="joint0" type="prismatic">
    <parent link="world"/>
    <child link="link0_x"/>
    <origin rpy="0 0 0" xyz="0 0 0"/>
    <axis xyz="1 0 0"/>
    <dynamics damping="1.0" friction="1.0"/>
    <limit lower="-1000" upper="1000" />
  </joint>
  
	<link name="link0_y">
		<inertial>
			<origin rpy="0.00000 -0.00000 0.00000" xyz="0.00000 0.00000 0.00000"/>
			<mass value="0.00000"/>
			<inertia ixx="0.00000" ixy="0" ixz="0" iyy="0.00000" iyz="0" izz="0.00000"/>
		</inertial>
	</link>
	<joint name="joint1" type="prismatic">
    <parent link="link0_x"/>
    <child link="link0_y"/>
    <origin rpy="0 0 0" xyz="0 0 0"/>
    <axis xyz="0 1 0"/>
    <dynamics damping="1.0" friction="1.0"/>
    <limit lower="-1000" upper="1000" />
  </joint>
	<link name="link0_z">
		<inertial>
			<origin rpy="0.00000 -0.00000 0.00000" xyz="0.00000 0.00000 0.00000"/>
			<mass value="0.00000"/>
			<inertia ixx="0.00000" ixy="0" ixz="0" iyy="0.00000" iyz="0" izz="0.00000"/>
		</inertial>
	</link>
	<joint name="joint2" type="prismatic">
    <parent link="link0_y"/>
    <child link="link0_z"/>
    <origin rpy="0 0 0" xyz="0 0 0"/>
    <axis xyz="0 0 1"/>
    <dynamics damping="1.0" friction="1.0"/>
    <limit lower="-1000" upper="1000" />
  </joint>
  
  <link name="link0_rotx">
		<inertial>
			<origin rpy="0.00000 -0.00000 0.00000" xyz="0.00000 0.00000 0.00000"/>
			<mass value="0.00000"/>
			<inertia ixx="0.00000" ixy="0" ixz="0" iyy="0.00000" iyz="0" izz="0.00000"/>
		</inertial>
	</link>
	<joint name="joint_rotx" type="continuous">
    <parent link="link0_z"/>
    <child link="link0_rotx"/>
    <origin rpy="0 0 0" xyz="0 0 0"/>
    <axis xyz="1 0 0"/>
    <dynamics damping="1.0" friction="1.0"/>
    <limit lower="-1000" upper="1000" />
  </joint>
  
    <link name="link0_roty">
		<inertial>
			<origin rpy="0.00000 -0.00000 0.00000" xyz="0.00000 0.00000 0.00000"/>
			<mass value="0.00000"/>
			<inertia ixx="0.00000" ixy="0" ixz="0" iyy="0.00000" iyz="0" izz="0.00000"/>
		</inertial>
	</link>
	<joint name="joint_roty" type="continuous">
    <parent link="link0_rotx"/>
    <child link="link0_roty"/>
    <origin rpy="0 0 0" xyz="0 0 0"/>
    <axis xyz="0 1 0"/>
    <dynamics damping="1.0" friction="1.0"/>
    <limit lower="-1000" upper="1000" />
  </joint>
  

  
  <link name="baseLink">
    <inertial>
      <origin rpy="0 0 0" xyz="0 0 0"/>
       <mass value="1.0"/>
       <inertia ixx="0.1" ixy="0" ixz="0" iyy="0.1" iyz="0" izz="0.1"/>
    </inertial>
  <visual>
			<origin rpy="0.00000 -0.00000 0.00000" xyz="0.00000 0.00000 0.00000"/>
			<geometry>
				<sphere radius="0.25000"/>
			</geometry>
			<material name="white">
        <color rgba="0.23 0.72 0.32 1"/>
      </material>
		</visual>
    <collision>
      <origin rpy="0 0 0" xyz="0. 0 0.0"/>
      <geometry>
       <sphere radius="0.25000"/>
      </geometry>
    </collision>
    
  </link>
  
  
  	
	<joint name="joint_rotz" type="continuous">
    <parent link="link0_roty"/>
    <child link="baseLink"/>
    <origin rpy="0 0 0" xyz="0 0 0"/>
    <axis xyz="0 0 1"/>
    <dynamics damping="1.0" friction="1.0"/>
  </joint>
  
  
   <link name="childA">
    <inertial>
      <origin rpy="-1.57080 0 1.57080" xyz="0.5 0 0"/>
      <mass value="1.0"/>
      <inertia ixx="0.1" ixy="0" ixz="0" iyy="0.1" iyz="0" izz="0.1"/>
    </inertial>
    <visual>
      <origin rpy="-1.57080 0 1.57080" xyz="0.5 0 0"/>
      <geometry>
        <capsule length="1." radius="0.08000"/>
      </geometry>
	   <material name="doormat0">
      <color rgba="0.8 0.8 0.3 1" />
      </material>

	  </visual>
     <collision>
       <origin rpy="-1.57080 0 1.57080" xyz="0.5 0 0"/>
       <geometry>
         <capsule length="1." radius="0.08000"/>
       </geometry>
     </collision>

   </link>
   <joint name="joint_baseLink_childA" type="continuous">
    <parent link="baseLink"/>
    <child link="childA"/>
	<dynamics damping="1.0" friction="0.0001"/>
    <origin xyz="0.25 0 0"/>
		<axis xyz="0 0 1"/>
  </joint>
  
  
   <link name="childB">
    <inertial>
      <origin rpy="-1.57080 0 1.57080" xyz="0.5 0 0"/>
      <mass value="1.0"/>
      <inertia ixx="0.048966669" ixy="0" ixz="0" iyy="0.046466667" iyz="0" izz="0.0041666669"/>
    </inertial>
    <visual>
      <origin rpy="-1.57080 0 1.57080" xyz="0.5 0 0"/>
      <geometry>
        <capsule length="1." radius="0.08000"/>
      </geometry>
	   <material name="doormat0">
      <color rgba="0.8 0.8 0.3 1" />
      </material>

	  </visual>
     <collision>
       <origin rpy="-1.57080 0 1.57080" xyz="0.5 0 0"/>
       <geometry>
         <capsule length="1." radius="0.08000"/>
       </geometry>
     </collision>

   </link>
  
   
   <joint name="joint_childA_childB" type="continuous">
    <parent link="childA"/>
    <child link="childB"/>
	<dynamics damping="1.0" friction="0.0001"/>
    <origin xyz="1. 0 0"/>
		<axis xyz="0 1 0"/>
  </joint>
</robot>

