<?xml version="0.0" ?>
<robot name="ant">
	<link name="torso">
		<inertial>
			<origin rpy="0.00000 -0.00000 0.00000" xyz="0.00000 0.00000 0.00000"/>
			<mass value="96.77605"/>
			<inertia ixx="5.70827" ixy="0" ixz="0" iyy="5.70827" iyz="0" izz="7.35187"/>
		</inertial>
		
		<visual>
			<origin rpy="0.00000 -0.00000 0.00000" xyz="0.00000 0.00000 0.00000"/>
			<geometry>
				<sphere radius="0.25000"/>
			</geometry>
			<material name="white">
        <color rgba="0.23 0.72 0.32 1"/>
      </material>
		</visual>
		
		
		<collision>
			<origin rpy="0.00000 -0.00000 0.00000" xyz="0.00000 0.00000 0.00000"/>
			<geometry>
				<sphere radius="0.25000"/>
			</geometry>
		</collision>
	
	</link>
	<link name="link0_3">
		<inertial>
			<origin rpy="0.00000 -0.00000 0.00000" xyz="0.10000 0.10000 0.00000"/>
			<mass value="7.83155"/>
			<inertia ixx="0.18134" ixy="0" ixz="0" iyy="0.18134" iyz="0" izz="0.29467"/>
		</inertial>
		<collision>
			<origin rpy="-1.57080 0.78540 -0.78540" xyz="0.10000 0.10000 0.00000"/>
			<geometry>
				<capsule length="0.28284" radius="0.08000"/>
			</geometry>
		</collision>
		<visual>
			<origin rpy="-1.57080 0.78540 -0.78540" xyz="0.10000 0.10000 0.00000"/>
			<geometry>
				<capsule length="0.28284" radius="0.08000"/>
			</geometry>
		</visual>
	</link>
	<link name="link0_5">
		<inertial>
			<origin rpy="0.00000 -0.00000 0.00000" xyz="0.20000 0.20000 0.00000"/>
			<mass value="13.51844"/>
			<inertia ixx="0.57220" ixy="0" ixz="0" iyy="0.57220" iyz="0" izz="1.02698"/>
		</inertial>
		<visual>
			<origin rpy="-1.57080 0.78540 -0.78540" xyz="0.20000 0.20000 0.00000"/>
			<geometry>
				<capsule length="0.56569" radius="0.08000"/>
			</geometry>
		</visual>
		<collision>
			<origin rpy="-1.57080 0.78540 -0.78540" xyz="0.20000 0.20000 0.00000"/>
			<geometry>
				<capsule length="0.56569" radius="0.08000"/>
			</geometry>
		</collision>
	</link>
	<link name="link0_18">
		<inertial>
			<origin rpy="0.00000 -0.00000 0.00000" xyz="0.10000 -0.10000 0.00000"/>
			<mass value="7.83155"/>
			<inertia ixx="0.18134" ixy="0" ixz="0" iyy="0.18134" iyz="0" izz="0.29467"/>
		</inertial>
		<collision>
			<origin rpy="1.57080 0.78540 0.78540" xyz="0.10000 -0.10000 0.00000"/>
			<geometry>
				<capsule length="0.28284" radius="0.08000"/>
			</geometry>
		</collision>
		<visual>
			<origin rpy="1.57080 0.78540 0.78540" xyz="0.10000 -0.10000 0.00000"/>
			<geometry>
				<capsule length="0.28284" radius="0.08000"/>
			</geometry>
		</visual>
	</link>
	<link name="link0_20">
		<inertial>
			<origin rpy="0.00000 -0.00000 0.00000" xyz="0.20000 -0.20000 0.00000"/>
			<mass value="13.51844"/>
			<inertia ixx="0.57220" ixy="0" ixz="0" iyy="0.57220" iyz="0" izz="1.02698"/>
		</inertial>
		<collision>
			<origin rpy="1.57080 0.78540 0.78540" xyz="0.20000 -0.20000 0.00000"/>
			<geometry>
				<capsule length="0.56569" radius="0.08000"/>
			</geometry>
		</collision>
		<visual>
			<origin rpy="1.57080 0.78540 0.78540" xyz="0.20000 -0.20000 0.00000"/>
			<geometry>
				<capsule length="0.56569" radius="0.08000"/>
			</geometry>
		</visual>
	</link>
	<link name="link0_8">
		<inertial>
			<origin rpy="0.00000 -0.00000 0.00000" xyz="-0.10000 0.10000 0.00000"/>
			<mass value="7.83155"/>
			<inertia ixx="0.18134" ixy="0" ixz="0" iyy="0.18134" iyz="0" izz="0.29467"/>
		</inertial>
		<collision>
			<origin rpy="-1.57080 -0.78540 0.78540" xyz="-0.10000 0.10000 0.00000"/>
			<geometry>
				<capsule length="0.28284" radius="0.08000"/>
			</geometry>
		</collision>
			<visual>
			<origin rpy="-1.57080 -0.78540 0.78540" xyz="-0.10000 0.10000 0.00000"/>
			<geometry>
				<capsule length="0.28284" radius="0.08000"/>
			</geometry>
		</visual>
	</link>
	<link name="link0_10">
		<inertial>
			<origin rpy="0.00000 -0.00000 0.00000" xyz="-0.20000 0.20000 0.00000"/>
			<mass value="13.51844"/>
			<inertia ixx="0.57220" ixy="0" ixz="0" iyy="0.57220" iyz="0" izz="1.02698"/>
		</inertial>
      <visual>
			<origin rpy="-1.57080 -0.78540 0.78540" xyz="-0.20000 0.20000 0.00000"/>
			<geometry>
				<capsule length="0.56569" radius="0.08000"/>
			</geometry>
		</visual>
		<collision>
			<origin rpy="-1.57080 -0.78540 0.78540" xyz="-0.20000 0.20000 0.00000"/>
			<geometry>
				<capsule length="0.56569" radius="0.08000"/>
			</geometry>
		</collision>
	</link>
	<link name="link0_13">
		<inertial>
			<origin rpy="0.00000 -0.00000 0.00000" xyz="-0.10000 -0.10000 0.00000"/>
			<mass value="7.83155"/>
			<inertia ixx="0.18134" ixy="0" ixz="0" iyy="0.18134" iyz="0" izz="0.29467"/>
		</inertial>
		<visual>
			<origin rpy="1.57080 -0.78540 -0.78540" xyz="-0.10000 -0.10000 0.00000"/>
			<geometry>
				<capsule length="0.28284" radius="0.08000"/>
			</geometry>
		</visual>
		<collision>
			<origin rpy="1.57080 -0.78540 -0.78540" xyz="-0.10000 -0.10000 0.00000"/>
			<geometry>
				<capsule length="0.28284" radius="0.08000"/>
			</geometry>
		</collision>
	</link>
	<link name="link0_15">
		<inertial>
			<origin rpy="0.00000 -0.00000 0.00000" xyz="-0.20000 -0.20000 0.00000"/>
			<mass value="13.51844"/>
			<inertia ixx="0.57220" ixy="0" ixz="0" iyy="0.57220" iyz="0" izz="1.02698"/>
		</inertial>
		<visual>
			<origin rpy="1.57080 -0.78540 -0.78540" xyz="-0.20000 -0.20000 0.00000"/>
			<geometry>
				<capsule length="0.56569" radius="0.08000"/>
			</geometry>
		</visual>
		<collision>
			<origin rpy="1.57080 -0.78540 -0.78540" xyz="-0.20000 -0.20000 0.00000"/>
			<geometry>
				<capsule length="0.56569" radius="0.08000"/>
			</geometry>
		</collision>
	</link>
	<joint name="hip_1" type="continuous">
		<parent link="torso"/>
		<child link="link0_3"/>
		<dynamics damping="1.0" friction="0.0001"/>
		<origin rpy="0.00000 -0.00000 0.00000" xyz="0.20000 0.20000 0.00000"/>
		
		<axis xyz="0.00000 0.00000 1.00000"/>
	</joint>
	<joint name="ankle_1" type="continuous">
		<parent link="link0_3"/>
		<child link="link0_5"/>
		<dynamics damping="1.0" friction="0.0001"/>
		<origin rpy="0.00000 -0.00000 0.00000" xyz="0.20000 0.20000 0.00000"/>
		
		
		<axis xyz="-1.00000 0.00000 0.00000"/>
	</joint>
	<joint name="hip_4" type="continuous">
		<parent link="torso"/>
		<child link="link0_18"/>
		<dynamics damping="1.0" friction="0.0001"/>
		<origin rpy="0.00000 -0.00000 0.00000" xyz="0.20000 -0.20000 0.00000"/>
		
		<axis xyz="0.00000 0.00000 1.00000"/>
	</joint>
	<joint name="ankle_4" type="continuous">
		<parent link="link0_18"/>
		<child link="link0_20"/>
		<dynamics damping="1.0" friction="0.0001"/>
		<origin rpy="0.00000 -0.00000 0.00000" xyz="0.20000 -0.20000 0.00000"/>
		
		
		<axis xyz="1.00000 0.00000 0.00000"/>
	</joint>
	<joint name="hip_2" type="continuous">
		<parent link="torso"/>
		<child link="link0_8"/>
		<dynamics damping="1.0" friction="0.0001"/>
		<origin rpy="0.00000 -0.00000 0.00000" xyz="-0.20000 0.20000 0.00000"/>
		
		<axis xyz="0.00000 0.00000 1.00000"/>
	</joint>
	<joint name="ankle_2" type="continuous">
		<parent link="link0_8"/>
		<child link="link0_10"/>
		<dynamics damping="1.0" friction="0.0001"/>
		<origin rpy="0.00000 -0.00000 0.00000" xyz="-0.20000 0.20000 0.00000"/>
		
		<axis xyz="-1.00000 0.00000 0.00000"/>
	</joint>
	<joint name="hip_3" type="continuous">
		<parent link="torso"/>
		<child link="link0_13"/>
		<dynamics damping="1.0" friction="0.0001"/>
		<origin rpy="0.00000 -0.00000 0.00000" xyz="-0.20000 -0.20000 0.00000"/>

		<axis xyz="0.00000 0.00000 1.00000"/>
	</joint>
	<joint name="ankle_3" type="continuous">
		<parent link="link0_13"/>
		<child link="link0_15"/>
		<dynamics damping="1.0" friction="0.0001"/>
		<origin rpy="0.00000 -0.00000 0.00000" xyz="-0.20000 -0.20000 0.00000"/>
		
		<axis xyz="1.00000 0.00000 0.00000"/>
	</joint>
</robot>
